Workbook

Sheet bitacora nocturno
A1: REGISTRO DIARIO DE INCIDENCIAS
A2: PERIODO ENERO- ABRIL 2026
A3: TURNOS: VESP Y NOCTURNO | D3: =FECHAS!D8 -> 46083 | G3: =FECHAS!G8 -> SEM 9 LIC
A4: ='concentrado nocturno'!A4:A5 -> Aula | B4: ='concentrado nocturno'!B4:B5 -> Gpo. | C4: ='concentrado nocturno'!C4:C5 -> Licenciatura | D4: Op | E4: 16:00 | F4: 17:00 | G4: 18:00 | H4: 19:00 | I4: 20:00 | J4: 21:00
A5: ='concentrado nocturno'!A6 -> CC1 | B5: ='concentrado nocturno'!B6 -> 0 | C5: ='concentrado nocturno'!C6 -> 0 | D5: ='concentrado nocturno'!D6 -> 0 | E5: ='concentrado nocturno'!E6 -> 390 | F5: ='concentrado nocturno'!F6 -> 390 | G5: ='concentrado nocturno'!G6 -> 2387 | H5: ='concentrado nocturno'!H6 -> 2387 | ... J5: ='concentrado nocturno'!J6 -> 0
A6: ='concentrado nocturno'!A7 -> CC2 | B6: ='concentrado nocturno'!B7 -> 0 | C6: ='concentrado nocturno'!C7 -> 0 | D6: ='concentrado nocturno'!D7 -> 0 | E6: ='concentrado nocturno'!E7 -> 0 | F6: ='concentrado nocturno'!F7 -> 0 | G6: ='concentrado nocturno'!G7 -> A161 | H6: ='concentrado nocturno'!H7 -> A161 | ... J6: ='concentrado nocturno'!J7 -> 0
A7: ='concentrado nocturno'!A8 -> CC3 | B7: ='concentrado nocturno'!B8 -> 0 | C7: ='concentrado nocturno'!C8 -> 0 | D7: ='concentrado nocturno'!D8 -> 0 | E7: ='concentrado nocturno'!E8 -> 1228 | F7: ='concentrado nocturno'!F8 -> 1228 | G7: ='concentrado nocturno'!G8 -> 335 | H7: ='concentrado nocturno'!H8 -> 335 | ... J7: ='concentrado nocturno'!J8 -> 0
A8: ='concentrado nocturno'!A9 -> CC4 | B8: ='concentrado nocturno'!B9 -> 0 | C8: ='concentrado nocturno'!C9 -> 0 | D8: ='concentrado nocturno'!D9 -> 0 | E8: ='concentrado nocturno'!E9 -> 0 | F8: ='concentrado nocturno'!F9 -> 0 | G8: ='concentrado nocturno'!G9 -> 436 | H8: ='concentrado nocturno'!H9 -> 0 | ... J8: ='concentrado nocturno'!J9 -> 0
A9: ='concentrado nocturno'!A10 -> CC5 | B9: ='concentrado nocturno'!B10 -> 0 | C9: ='concentrado nocturno'!C10 -> 0 | D9: ='concentrado nocturno'!D10 -> 0 | E9: ='concentrado nocturno'!E10 -> 0 | F9: ='concentrado nocturno'!F10 -> 1035 | G9: ='concentrado nocturno'!G10 -> 1228 | H9: ='concentrado nocturno'!H10 -> 1228 | ... J9: ='concentrado nocturno'!J10 -> 0
A10: ='concentrado nocturno'!A11 -> 1 | B10: ='concentrado nocturno'!B11 -> 421-13/521-14 | C10: ='concentrado nocturno'!C11 -> Psicologia | D10: ='concentrado nocturno'!D11 -> 11DV, 8AN, 5BN | E10: ='concentrado nocturno'!E11 -> 0 | F10: ='concentrado nocturno'!F11 -> 2396 | G10: ='concentrado nocturno'!G11 -> 2396 | H10: ='concentrado nocturno'!H11 -> 1246 | ... J10: ='concentrado nocturno'!J11 -> 0
A11: ='concentrado nocturno'!A12 -> 2 | B11: ='concentrado nocturno'!B12 -> 721-8-821-9 | C11: ='concentrado nocturno'!C12 -> Psicologia | D11: ='concentrado nocturno'!D12 -> 0 | E11: ='concentrado nocturno'!E12 -> 2325 | F11: ='concentrado nocturno'!F12 -> 1456 | G11: ='concentrado nocturno'!G12 -> A121 | H11: ='concentrado nocturno'!H12 -> 2206 | ... J11: ='concentrado nocturno'!J12 -> 0
A12: ='concentrado nocturno'!A13 -> 2 | B12: ='concentrado nocturno'!B13 -> 421-13/521-14 | C12: ='concentrado nocturno'!C13 -> Compu | D12: ='concentrado nocturno'!D13 -> 0 | E12: ='concentrado nocturno'!E13 -> 390 CC | F12: ='concentrado nocturno'!F13 -> 390 CC | G12: ='concentrado nocturno'!G13 -> 436 CC | H12: ='concentrado nocturno'!H13 -> 0 | ... J12: ='concentrado nocturno'!J13 -> 0
A13: ='concentrado nocturno'!A14 -> 3 | B13: ='concentrado nocturno'!B14 -> 221-14 | C13: ='concentrado nocturno'!C14 -> Psicologia | D13: ='concentrado nocturno'!D14 -> 8CN | E13: ='concentrado nocturno'!E14 -> A114 | F13: ='concentrado nocturno'!F14 -> A114 | G13: ='concentrado nocturno'!G14 -> A158 | H13: ='concentrado nocturno'!H14 -> 0 | ... J13: ='concentrado nocturno'!J14 -> 0
A14: ='concentrado nocturno'!A15 -> 3 | B14: ='concentrado nocturno'!B15 -> 1031-13/1131-14 | C14: ='concentrado nocturno'!C15 -> Psicologia | D14: ='concentrado nocturno'!D15 -> 0 | E14: ='concentrado nocturno'!E15 -> 0 | F14: ='concentrado nocturno'!F15 -> 0 | G14: ='concentrado nocturno'!G15 -> 0 | H14: ='concentrado nocturno'!H15 -> 2396 | ... J14: ='concentrado nocturno'!J15 -> 2326
A15: ='concentrado nocturno'!A16 -> 4 | B15: ='concentrado nocturno'!B16 -> 531-14 | C15: ='concentrado nocturno'!C16 -> FINANZAS | D15: ='concentrado nocturno'!D16 -> 0 | E15: ='concentrado nocturno'!E16 -> S 003 | F15: ='concentrado nocturno'!F16 -> S 003 | G15: ='concentrado nocturno'!G16 -> S 003 | H15: ='concentrado nocturno'!H16 -> 2543 | ... J15: ='concentrado nocturno'!J16 -> 1836
A16: ='concentrado nocturno'!A17 -> 4 | B16: ='concentrado nocturno'!B17 -> 821-14 | C16: ='concentrado nocturno'!C17 -> Psicologia | D16: ='concentrado nocturno'!D17 -> 0 | E16: ='concentrado nocturno'!E17 -> 1303 | F16: ='concentrado nocturno'!F17 -> 1303 | G16: ='concentrado nocturno'!G17 -> S 103 | H16: ='concentrado nocturno'!H17 -> 0 | ... J16: ='concentrado nocturno'!J17 -> 0
... A26: ='concentrado nocturno'!A27 -> 104 | B26: ='concentrado nocturno'!B27 -> 521-9 | C26: ='concentrado nocturno'!C27 -> Negocios | D26: ='concentrado nocturno'!D27 -> 8DV | E26: ='concentrado nocturno'!E27 -> A191 | F26: ='concentrado nocturno'!F27 -> A191 | G26: ='concentrado nocturno'!G27 -> 2543 | H26: ='concentrado nocturno'!H27 -> A55 | ... J26: ='concentrado nocturno'!J27 -> 0
A28: =A1 -> REGISTRO DIARIO DE INCIDENCIAS
A29: =A2 -> PERIODO ENERO- ABRIL 2026
A30: =A3 -> TURNOS: VESP Y NOCTURNO | D30: =D3 -> 46083 | G30: =G3 -> SEM 9 LIC
A31: =A4 -> Aula | B31: =B4 -> Gpo. | C31: =C4 -> Licenciatura | D31: =D4 -> Op | E31: =E4 -> 16:00 | F31: =F4 -> 17:00 | G31: =G4 -> 18:00 | H31: =H4 -> 19:00 | ... J31: =J4 -> 21:00
A32: ='concentrado nocturno'!A28 -> 201 | B32: ='concentrado nocturno'!B28 -> 1431-14 | C32: ='concentrado nocturno'!C28 -> Civil | D32: ='concentrado nocturno'!D28 -> 8AV, 5BV | E32: ='concentrado nocturno'!E28 -> 0 | F32: ='concentrado nocturno'!F28 -> 0 | G32: ='concentrado nocturno'!G28 -> 0 | H32: ='concentrado nocturno'!H28 -> A145 | ... J32: ='concentrado nocturno'!J28 -> A261
A33: ='concentrado nocturno'!A29 -> 202 | B33: ='concentrado nocturno'!B29 -> 831-14 | C33: ='concentrado nocturno'!C29 -> Psicologia | D33: ='concentrado nocturno'!D29 -> 0 | E33: ='concentrado nocturno'!E29 -> 0 | F33: ='concentrado nocturno'!F29 -> 0 | G33: ='concentrado nocturno'!G29 -> 0 | H33: ='concentrado nocturno'!H29 -> S 001 | ... J33: ='concentrado nocturno'!J29 -> 1360
A34: ='concentrado nocturno'!A30 -> 203 Sim | B34: ='concentrado nocturno'!B30 -> 0 | C34: ='concentrado nocturno'!C30 -> Compu | D34: ='concentrado nocturno'!D30 -> 0 | E34: ='concentrado nocturno'!E30 -> 0 | F34: ='concentrado nocturno'!F30 -> 0 | G34: ='concentrado nocturno'!G30 -> 0 | H34: ='concentrado nocturno'!H30 -> 1035 | ... J34: ='concentrado nocturno'!J30 -> 0
A35: ='concentrado nocturno'!A31 -> 204 | B35: ='concentrado nocturno'!B31 -> 731-13/831-14 | C35: ='concentrado nocturno'!C31 -> Electro | D35: ='concentrado nocturno'!D31 -> 0 | E35: ='concentrado nocturno'!E31 -> 0 | F35: ='concentrado nocturno'!F31 -> 0 | G35: ='concentrado nocturno'!G31 -> 0 | H35: ='concentrado nocturno'!H31 -> 2310 s302 | ... J35: ='concentrado nocturno'!J31 -> 2310 s302
A36: ='concentrado nocturno'!A32 -> 205 | B36: ='concentrado nocturno'!B32 -> 1121-14 | C36: ='concentrado nocturno'!C32 -> Psicologia | D36: ='concentrado nocturno'!D32 -> 8CV, 2BN | E36: ='concentrado nocturno'!E32 -> 2396 | F36: ='concentrado nocturno'!F32 -> 1769 | G36: ='concentrado nocturno'!G32 -> 2372 | H36: ='concentrado nocturno'!H32 -> 0 | ... J36: ='concentrado nocturno'!J32 -> 0
A37: ='concentrado nocturno'!A33 -> 205 | B37: ='concentrado nocturno'!B33 -> 0 | C37: ='concentrado nocturno'!C33 -> 0 | D37: ='concentrado nocturno'!D33 -> 0 | E37: ='concentrado nocturno'!E33 -> 0 | F37: ='concentrado nocturno'!F33 -> 0 | G37: ='concentrado nocturno'!G33 -> 0 | H37: ='concentrado nocturno'!H33 -> 0 | ... J37: ='concentrado nocturno'!J33 -> 0
A38: ='concentrado nocturno'!A34 -> 206 | B38: ='concentrado nocturno'!B34 -> 231-14 | C38: ='concentrado nocturno'!C34 -> Civil | D38: ='concentrado nocturno'!D34 -> 0 | E38: ='concentrado nocturno'!E34 -> 0 | F38: ='concentrado nocturno'!F34 -> 0 | G38: ='concentrado nocturno'!G34 -> 0 | H38: ='concentrado nocturno'!H34 -> A141 | ... J38: ='concentrado nocturno'!J34 -> 848
A39: ='concentrado nocturno'!A35 -> 207 | B39: ='concentrado nocturno'!B35 -> 231-14 | C39: ='concentrado nocturno'!C35 -> Psicologia | D39: ='concentrado nocturno'!D35 -> 0 | E39: ='concentrado nocturno'!E35 -> 0 | F39: ='concentrado nocturno'!F35 -> 0 | G39: ='concentrado nocturno'!G35 -> 0 | H39: ='concentrado nocturno'!H35 -> 2409 | ... J39: ='concentrado nocturno'!J35 -> 1769
A40: ='concentrado nocturno'!A37 -> 209 | B40: ='concentrado nocturno'!B37 -> 1331-13/1431-14 | C40: ='concentrado nocturno'!C37 -> Industrial | D40: ='concentrado nocturno'!D37 -> 0 | E40: ='concentrado nocturno'!E37 -> 964 | F40: ='concentrado nocturno'!F37 -> 964 | G40: ='concentrado nocturno'!G37 -> 2130 | H40: ='concentrado nocturno'!H37 -> S 218 | ... J40: ='concentrado nocturno'!J37 -> 2182
A41: ='concentrado nocturno'!A36 -> 208 | B41: ='concentrado nocturno'!B36 -> 821-9 | C41: ='concentrado nocturno'!C36 -> Industrial | D41: ='concentrado nocturno'!D36 -> 0 | E41: ='concentrado nocturno'!E36 -> S 209 | F41: ='concentrado nocturno'!F36 -> S 209 | G41: ='concentrado nocturno'!G36 -> S 209 | H41: ='concentrado nocturno'!H36 -> 2130 | ... J41: ='concentrado nocturno'!J36 -> 0
A42: ='concentrado nocturno'!A38 -> 210 | B42: ='concentrado nocturno'!B38 -> 121-13 | C42: ='concentrado nocturno'!C38 -> Psicologia | D42: ='concentrado nocturno'!D38 -> 0 | E42: ='concentrado nocturno'!E38 -> 0 | F42: ='concentrado nocturno'!F38 -> 0 | G42: ='concentrado nocturno'!G38 -> 0 | H42: ='concentrado nocturno'!H38 -> 1581 | ... J42: ='concentrado nocturno'!J38 -> 0
A43: ='concentrado nocturno'!A39 -> 211 | B43: ='concentrado nocturno'!B39 -> 1431-14 | C43: ='concentrado nocturno'!C39 -> FINANZAS | D43: ='concentrado nocturno'!D39 -> 0 | E43: ='concentrado nocturno'!E39 -> 0 | F43: ='concentrado nocturno'!F39 -> 0 | G43: ='concentrado nocturno'!G39 -> 0 | H43: ='concentrado nocturno'!H39 -> A99 | ... J43: ='concentrado nocturno'!J39 -> 1990
A44: ='concentrado nocturno'!A40 -> 211 | B44: ='concentrado nocturno'!B40 -> 1421-14 | C44: ='concentrado nocturno'!C40 -> Psicologia | D44: ='concentrado nocturno'!D40 -> 0 | E44: ='concentrado nocturno'!E40 -> 2372 | F44: ='concentrado nocturno'!F40 -> A121 | G44: ='concentrado nocturno'!G40 -> 1456 | H44: ='concentrado nocturno'!H40 -> 0 | ... J44: ='concentrado nocturno'!J40 -> 0
A45: ='concentrado nocturno'!A41 -> 212 | B45: ='concentrado nocturno'!B41 -> 421-8 | C45: ='concentrado nocturno'!C41 -> Industrial | D45: ='concentrado nocturno'!D41 -> 0 | E45: ='concentrado nocturno'!E41 -> 765 | F45: ='concentrado nocturno'!F41 -> 765 | G45: ='concentrado nocturno'!G41 -> S. 301-A | H45: ='concentrado nocturno'!H41 -> S. 301-A | ... J45: ='concentrado nocturno'!J41 -> 964
A46: ='concentrado nocturno'!A43 -> 213 | B46: ='concentrado nocturno'!B43 -> 521-14 | C46: ='concentrado nocturno'!C43 -> FINANZAS | D46: ='concentrado nocturno'!D43 -> 0 | E46: ='concentrado nocturno'!E43 -> 1228 CC | F46: ='concentrado nocturno'!F43 -> A97 | G46: ='concentrado nocturno'!G43 -> A166 | H46: ='concentrado nocturno'!H43 -> 0 | ... J46: ='concentrado nocturno'!J43 -> 0
A47: ='concentrado nocturno'!A44 -> 214 | B47: ='concentrado nocturno'!B44 -> 0 | C47: ='concentrado nocturno'!C44 -> 0 | D47: ='concentrado nocturno'!D44 -> 0 | E47: ='concentrado nocturno'!E44 -> 0 | F47: ='concentrado nocturno'!F44 -> 0 | G47: ='concentrado nocturno'!G44 -> 0 | H47: ='concentrado nocturno'!H44 -> 0 | ... J47: ='concentrado nocturno'!J44 -> 0
A48: ='concentrado nocturno'!A45 -> 215 | B48: ='concentrado nocturno'!B45 -> 1421-14 | C48: ='concentrado nocturno'!C45 -> Compu | D48: ='concentrado nocturno'!D45 -> 0 | E48: ='concentrado nocturno'!E45 -> 0 | F48: ='concentrado nocturno'!F45 -> 1035 CC | G48: ='concentrado nocturno'!G45 -> A161 CC | H48: ='concentrado nocturno'!H45 -> A161 CC | ... J48: ='concentrado nocturno'!J45 -> 0
A49: ='concentrado nocturno'!A46 -> 216 | B49: ='concentrado nocturno'!B46 -> 821-14 | C49: ='concentrado nocturno'!C46 -> Mecatronica | D49: ='concentrado nocturno'!D46 -> 0 | E49: ='concentrado nocturno'!E46 -> 0 | F49: ='concentrado nocturno'!F46 -> 2387 | G49: ='concentrado nocturno'!G46 -> 1534 | H49: ='concentrado nocturno'!H46 -> S 001 | ... J49: ='concentrado nocturno'!J46 -> 0
A50: ='concentrado nocturno'!A47 -> 217 | B50: ='concentrado nocturno'!B47 -> 0 | C50: ='concentrado nocturno'!C47 -> 0 | D50: ='concentrado nocturno'!D47 -> 0 | E50: ='concentrado nocturno'!E47 -> 0 | F50: ='concentrado nocturno'!F47 -> 0 | G50: ='concentrado nocturno'!G47 -> 0 | H50: ='concentrado nocturno'!H47 -> 0 | ... J50: ='concentrado nocturno'!J47 -> 0
...

Sheet concentrado nocturno
A1: Concentrado General De Catedráticos y Grupos.
A3: a
A4: Aula | B4: Gpo. | C4: Licenciatura | D4: Opt | E4: Lunes | K4: Martes | Q4: Miércoles | W4: Jueves | AC4: Viernes | AI4: Aula
E5: 4:00 | F5: 5:00 | G5: 6:00 | H5: 7:00 | I5: 8:00 | J5: 9:00 | K5: 4:00 | L5: 5:00 | M5: 6:00 | N5: 7:00 | O5: 8:00 | P5: 9:00 | Q5: 4:00 | R5: 5:00 | S5: 6:00 | T5: 7:00 | U5: 8:00 | V5: 9:00 | W5: 4:00 | X5: 5:00 | Y5: 6:00 | Z5: 7:00 | AA5: 8:00 | AB5: 9:00 | AC5: 4:00 | AD5: 5:00 | AE5: 6:00 | AF5: 7:00 | AG5: 8:00 | AH5: 9:00
A6: CC1 | E6: 390 | F6: 390 | G6: 2387 | H6: 2387 | K6: 1094 | L6: 1094 | P6: 634 | S6: 2130 | T6: 2130 | X6: 1094 | AF6: 1228 | AG6: 1228 | AI6: =+A6 -> CC1
A7: CC2 | G7: A161 | H7: A161 | I7: 634 | L7: 1035 | M7: 1035 | Q7: 634 | R7: 634 | S7: 634 | T7: 1517 | U7: 634 | V7: 634 | W7: 634 | Y7: 1534 | Z7: A182 | AA7: A182 | AD7: A97 | AE7: A238 | AF7: A161 | AI7: =A7 -> CC2
A8: CC3 | E8: 1228 | F8: 1228 | G8: 335 | H8: 335 | I8: 335 | L8: 2387 | R8: A97 | S8: A97 | T8: 1035 | U8: 1836 | V8: 1836 | X8: A242 | Z8: A38 | AC8: 1228 | AI8: =A8 -> CC3
A9: CC4 | G9: 436 | I9: A99 | M9: 1534 | N9: 2448 | O9: 2448 | Q9: 1228 | S9: A38 | T9: 2448 | U9: 1517 | W9: 390 | Z9: 2448 | AA9: 634 | AB9: 634 | AC9: A161 | AD9: A161 | AF9: 2448 | AG9: 2448 | AI9: =A9 -> CC4
A10: CC5 | F10: 1035 | G10: 1228 | H10: 1228 | I10: 1836 | K10: 436 | O10: 1836 | P10: 1836 | Z10: A242 | AA10: A242 | AE10: 634 | AF10: A96 | AI10: =A10 -> CC5
A11: 1 | B11: 421-13/521-14 | C11: Psicologia | D11: 11DV, 8AN, 5BN | F11: 2396 | G11: 2396 | H11: 1246 | K11: 1567 | L11: A133 | M11: A133 | N11: 2336 | O11: 2336 | R11: 2396 | S11: A234 | T11: 2223 | U11: 2223 | W11: A262 | X11: A133 | Y11: A133 | Z11: 2336 | AA11: 2336 | AC11: 2396 | AD11: A234 | AE11: A234 | AF11: 2223 | AG11: 2223 | AH11: 1567 | AI11: =A11 -> 1
A12: 2 | B12: 721-8-821-9 | C12: Psicologia | E12: 2325 | F12: 1456 | G12: A121 | H12: 2206 | I12: 634 CC | K12: 2396 | L12: 2468 | M12: 2468 | N12: 382 | O12: 634 | Q12: 2325 | R12: A121 | S12: 2396 | T12: 382 | U12: 634 CC | W12: 634 CC | X12: 2468 | Y12: 2468 | Z12: 1456 | AA12: 2206 | AD12: 2206 | AE12: 2206 | AF12: A121 | AG12: 2396 | AI12: =A12 -> 2
A13: 2 | B13: 421-13/521-14 | C13: Compu | E13: 390 CC | F13: 390 CC | G13: 436 CC | K13: 436 CC | P13: A263 | Q13: 436 | R13: 436 | S13: A161 | W13: 390 cc | AC13: A161 CC | AD13: A161 CC | AE13: 1567 S102 | AF13: CCIG | AG13: CCIG | AI13: =A13 -> 2
A14: 3 | B14: 221-14 | C14: Psicologia | D14: 8CN | E14: A114 | F14: A114 | G14: A158 | K14: 2325 | L14: 2396 | M14: 1602 | N14: 1435 | O14: 1435 | Q14: 2396 | R14: A114 | S14: A114 | W14: 2325 | X14: 1602 | Y14: A158 | Z14: 1435 | AA14: 1435 | AB14: A263 | AC14: 1602 | AD14: 1567 S 315 | AE14: 2396 | AI14: =A14 -> 3
A15: 3 | B15: 1031-13/1131-14 | C15: Psicologia | H15: 2396 | I15: 2326 | J15: 2326 | T15: 2396 | U15: 2396 | V15: A121 | AG15: A121 | AI15: =A15 -> 3
A16: 4 | B16: 531-14 | C16: FINANZAS | E16: S 003 | F16: S 003 | G16: S 003 | H16: 2543 | I16: A97 | J16: 1836 | N16: 2476 s306 | O16: 2476 s306 | P16: 1836 cc | T16: A166 | U16: A97 | V16: 1836 CC | Z16: 2476 | AA16: 2476 | AB16: A166 | AF16: A166 | AG16: A166 | AH16: A97 | AI16: =A16 -> 4
A17: 4 | B17: 821-14 | C17: Psicologia | E17: 1303 | F17: 1303 | G17: S 103 | K17: A99 | L17: 1456 | M17: 1303 | Q17: 2517 | R17: 1846 | S17: 1846 | W17: 2517 | X17: 1456 | Y17: A99 | AC17: 2517 | AD17: 1846 | AE17: 1846 | AI17: =A17 -> 4
A18: 5 | B18: 721-8/821-9 | C18: Civil | D18: 2BV | E18: A145 | F18: A145 | G18: 2306 | H18: GEVA | I18: GEVA | J18: 2401 | K18: 1384 | L18: 2395 | M18: 2395 | N18: GEVA | O18: 2401 | P18: 2401 | Q18: 1887 | R18: A43 | S18: 1152 | T18: 2231 | U18: 2231 | W18: A43 | X18: 2395 | Y18: 2395 | Z18: 2306 | AA18: 2306 | AC18: 1887 | AD18: 1887 | AE18: 1152 | AF18: 1384 | AG18: 1384 | AI18: =A18 -> 5
A19: 7 | B19: 721-8/821-9 | C19: FINANZAS | E19: A228 | F19: A96 | G19: A96 | H19: A238 | I19: A238 | K19: A228 | L19: 160 | M19: 160 | N19: 2448 CC | O19: 2448 CC | Q19: A99 | R19: A96 | S19: 2040 | T19: A228 | U19: A228 | W19: A99 | X19: 160 | Y19: 160 | Z19: 2040 | AA19: 2040 | AC19: A99 | AD19: A99 | AE19: A238 CC2 | AF19: A96 CC | AG19: 2448 CC4 | AI19: =A19 -> 7
A20: 8 | B20: 821-9 | C20: Negocios | D20: 2AV | E20: A237 | F20: 1246 | G20: A55 | H20: 2312 | I20: 2312 | K20: A234 | L20: A36 | M20: A36 | N20: A55 | O20: A55 | Q20: A234 | R20: A234 | S20: A230 | T20: A230 | U20: 2312 | X20: A36 | Y20: A36 | Z20: 1246 | AA20: A230 | AC20: A237 | AD20: A237 | AE20: A55 | AF20: 98 | AG20: 98 | AI20: =A20 -> 8
A21: 9 | B21: 221-9 | C21: FINANZAS | D21: 5DV | E21: 1567 | F21: 2312 | G21: A97 | H21: A96 | I21: 1836 CC | K21: 1990 | L21: 2451 | M21: 2451 | N21: A99 | O21: 1836 CC | R21: 2451 | S21: 2451 | T21: A96 | U21: 1836 cc | W21: 1990 | X21: 2451 | Y21: 2451 | Z21: A96 | AA21: A99 | AC21: 1990 | AD21: 2312 | AE21: A97 | AF21: A99 | AG21: 2163 S 101 | AH21: 2163 | AI21: =A21 -> 9
A22: 101 | B22: 221-9 | C22: Civil | D22: 2CV | E22: 2543 | F22: A141 | G22: A141 | H22: A136 | I22: A136 | J22: JUPJ | K22: A141 | L22: A78 | M22: A78 | N22: A136 | O22: A200 | Q22: 634 CC | R22: 634 CC | S22: 634 CC | T22: 1502 S 103 | U22: 1502 S 103 | W22: A200 | X22: A78 | Y22: A78 | Z22: 1502 | AA22: 1502 | AC22: A200 | AD22: A200 | AE22: 634 CC5 | AF22: A200 | AG22: 2163 | AI22: =A22 -> 101
A23: 102 | B23: 531-14 | C23: Civil | H23: 2401 | I23: A169 | J23: A169 | P23: A43 | T23: 2401 | U23: 2401 | V23: A169 | AB23: A43 | AF23: A43 | AG23: A43 | AH23: 1567 S 001 | AI23: =A23 -> 102
A24: 102 | B24: 521-14 | C24: Civil | D24: 8BV, 5CN | E24: 1887 | F24: 1887 | G24: A136 | K24: 1887 | L24: 2336 | M24: 2336 | N24: A78 | O24: A78 | Q24: A183 | R24: A136 | S24: A136 | W24: 1887 | X24: 2336 | Y24: 2336 | Z24: A78 | AA24: A78 | AE24: 1567 | AI24: =A24 -> 102
A25: 103 | B25: 821-14 | C25: Civil | D25: 5AV, 8BN | E25: 2401 | F25: A136 | G25: 1246 | K25: 1152 | L25: 1152 | M25: A136 | N25: 2468 | O25: 2468 | Q25: 1384 | R25: 2476 | S25: 2476 | U25: A260 S101 | V25: A260 S101 | W25: 2401 | X25: 1152 | Y25: A136 | Z25: 2468 | AA25: 2468 | AC25: 1384 | AD25: 2476 | AE25: 2476 | AI25: =A25 -> 103
A26: 103 | B26: 1131-14 | C26: Civil | H26: 2306 | I26: 2306 | J26: S 101 | P26: A200 | T26: A169 | AB26: A169 | AF26: 2306 | AG26: A200 | AH26: 2163 S 101 | AI26: =A26 -> 103
A27: 104 | B27: 521-9 | C27: Negocios | D27: 8DV | E27: A191 | F27: A191 | G27: 2543 | H27: A55 | I27: 2472 | K27: A244 | L27: A244 | N27: A198 | O27: 2166 | Q27: S 201 | T27: 2472 | U27: 2166 | W27: A244 | X27: A244 | Y27: A198 | Z27: A55 | AA27: A55 | AC27: A191 | AF27: A55 | AG27: 2472 | AI27: =A27 -> 104
A28: 201 | B28: 1431-14 | C28: Civil | D28: 8AV, 5BV | H28: A145 | I28: 2338 | J28: A261 | L28: A160 s007 | M28: A160 s007 | N28: A145 | O28: A261 | P28: A261 | Q28: 1567 S 301 | R28: A78 | S28: A78 | T28: A145 | U28: 2338 | V28: 2338 | X28: A160 s007 | Y28: A160 s007 | Z28: 1152 | AA28: 1887 | AB28: 1887 | AD28: A78 | AE28: A78 | AF28: 1152 | AG28: 990 | AH28: 990 | AI28: =A28 -> 201
A29: 202 | B29: 831-14 | C29: Psicologia | H29: S 001 | I29: 2206 | J29: 1360 | N29: 2409 | O29: 2409 | P29: 2166 | V29: 2166 | Z29: 2206 | AA29: 1360 | AB29: 2409 | AH29: 2206 | AI29: =A29 -> 202
A30: 203 Sim | C30: Compu | H30: 1035 | I30: 1035 | Z30: 1035 | AE30: 1035 | AF30: 1035 | AG30: 1035 | AI30: =A30 -> 203 Sim
A31: 204 | B31: 731-13/831-14 | C31: Electro | H31: 2310 s302 | I31: 2310 s302 | J31: 2310 s302 | M31: 1662 | N31: 1662 | O31: 1662 | P31: A79 | S31: 1567 s315 | V31: A79 | Y31: 1662 | Z31: 1662 | AA31: 2310 | AB31: 2310 | AE31: 2310 | AH31: A79 | AI31: =A31 -> 204
A32: 205 | B32: 1121-14 | C32: Psicologia | D32: 8CV, 2BN | E32: 2396 | F32: 1769 | G32: 2372 | K32: A263 | L32: 2468 sln02 | M32: 2468 sln02 | N32: A160 | O32: A160 | Q32: 2372 | R32: 382 | S32: 382 | W32: 2396 | X32: 2468 S002 | Y32: 2468 S002 | Z32: A160 | AA32: A160 | AC32: A263 | AD32: 2396 | AE32: A263 | AI32: =A32 -> 205
A33: 205 | AI33: =A33 -> 205
A34: 206 | B34: 231-14 | C34: Civil | H34: A141 | I34: A141 | J34: 848 | N34: 245 | O34: 245 | P34: 634 cc | T34: 848 | U34: 848 | V34: 634 CC | Z34: A141 | AA34: 634 CC | AB34: 634 CC | AF34: 1502 | AG34: 1502 | AH34: 1836 sln211 | AI34: =A34 -> 206
A35: 207 | B35: 231-14 | C35: Psicologia | H35: 2409 | I35: 2409 | J35: 1769 | N35: 2390 | O35: A262 | P35: A262 | T35: 2390 | U35: A234 | V35: A234 | Z35: 2409 | AA35: 2409 | AB35: 1360 | AF35: A234 | AG35: 1360 | AH35: 2390 | AI35: =A35 -> 207
A36: 208 | B36: 821-9 | C36: Industrial | E36: S 209 | F36: S 209 | G36: S 209 | H36: 2130 | I36: 1562 | K36: S 209 | N36: A103 | O36: A103 | Q36: S 209 | R36: S 209 | S36: 2130 CC | T36: 2130 CC | U36: 1562 | W36: A95 | Z36: A103 | AA36: 1562 | AC36: A95 | AD36: 1562 | AE36: 1562 | AF36: 2130 | AG36: A103 | AI36: =A36 -> 208 | XDT36: =SUM(A36:XDS36) -> 12486
A37: 209 | B37: 1331-13/1431-14 | C37: Industrial | E37: 964 | F37: 964 | G37: 2130 | H37: S 218 | I37: 2182 | J37: 2182 | K37: 964 | N37: A182 | O37: 1562 | P37: A103 | Q37: 964 | R37: 1567 | T37: A95 | U37: A95 | V37: A182 | Z37: 765 | AA37: 2182 | AB37: 1579 | AF37: A103 | AG37: 1562 | AH37: 2182 | AI37: =A37 -> 209
A38: 210 | B38: 121-13 | C38: Psicologia | H38: 1581 | I38: 1581 | M38: 382 | N38: 1602 | O38: 1602 | T38: A231 | U38: A231 | X38: 1581 | Z38: 1602 | AA38: A231 | AI38: =A38 -> 210
A39: 211 | B39: 1431-14 | C39: FINANZAS | H39: A99 | I39: A99 CC | J39: 1990 | N39: A166 | O39: A99 | P39: 1990 | T39: 2448 CC | U39: A166 | V39: 1990 | Z39: 2448 CC4 | AA39: A238 | AB39: A238 | AF39: 2448 CC4 | AG39: 990 s201 | AH39: 990 s201 | AI39: =A39 -> 211
A40: 211 | B40: 1421-14 | C40: Psicologia | E40: 2372 | F40: A121 | G40: 1456 | K40: 1303 | L40: 1303 | M40: A121 | Q40: 1303 | R40: 1303 | S40: A121 | W40: 1456 | X40: S219 | Y40: S219 | AC40: 2372 | AD40: 2372 | AE40: A121 | AH40: 1836 | AI40: =A40 -> 211
A41: 212 | B41: 421-8 | C41: Industrial | E41: 765 | F41: 765 | G41: S. 301-A | H41: S. 301-A | I41: S. 301-A | J41: 964 | K41: S. 301-A | L41: 765 | M41: 765 | N41: S. 301-A | O41: S. 301-A | P41: 1581 | Q41: S. 301-A | T41: S. 301-A | U41: S. 301-A | V41: 1581 | W41: 1581 | X41: 964 | Y41: 964 | Z41: S. 301-A | AA41: S 301-A | AB41: 964 | AC41: S. 301-A | AF41: S. 301-A | AG41: S. 301-A | AH41: 1567 S 001 | AI41: =A41 -> 212
...

Sheet FECHAS
D8: 46083 | G8: SEM 9 LIC | J8: =+TODAY() -> 46085
D9: 46084
D10: 46085
D11: 46086
D12: 46087
D13: 46088

Sheet bitacora SABADO
A1: Registro diario de incidencias
A2: Periodo ENERO -ABRIL 2026
A3: MATUTINO | C3: =FECHAS!D13 -> 46088 | G3: =FECHAS!G8 -> SEM 9 LIC
A4: SALON | B4: Gpo. | C4: Licenciatura | D4: 0.29166667 | E4: 0.32638889 | F4: 0.36111111 | G4: 0.39583333 | H4: 0.44444444
A6: 2 | B6: 231-14 | C6: ING. INDUSTRIAL | D6: A182 | E6: A182 | F6: 1579 | G6: 1579
A7: 3 | B7: 701-13/801-14 | C7: ING. ELECTRO | E7: A232 | F7: 2179 | G7: 2179 | H7: 2179
A8: 4 | B8: 201-14 | C8: ING. ELECTRO | D8: 1534 | E8: 1534 | F8: 2310 | G8: 2310 | H8: 2310
A9: CC
A10: 5 | B10: 331-13/431-14 | C10: ING. INDUSTRIAL | D10: 765 | E10: 1579 | F10: A95
A11: 7
A12: 8 | B12: 201-14 | C12: NEGOCIOS | D12: 2182 | E12: 2182 | F12: 2182
A13: 9 | B13: 301-13/401-14 | C13: ING. INDUSTRIAL | D13: A79 | E13: A79 | F13: A79
A14: 101
A15: 102 | B15: 201-14 | C15: ING. CIVIL | D15: 2338 | E15: 245 | F15: 2338 | G15: 848 | H15: 848
A16: 103 | B16: 231-14 | C16: ING. CIVIL | D16: 245 | E16: 848 | F16: 848 | G16: 1502 | H16: 1502
A17: 104 | B17: 231-14 | C17: MECATRONICA | D17: 2154 | E17: 2154 | F17: 2154
A18: 201
A19: 212
A23: Observaciones:

Sheet Hoja5
